Workbook

Sheet Portfolio Maths
B1: Mathematics
B2: (per annum) | D2: (in lakhs) | J2: Sector | K2: Growth | L2: Government | M2: Profitability | N2: Visibility | O2: Structural Growth | P2: Risk | Q2: Final Score (/10) | R2: Sector Weights | S2: Investment Amount
B3: Revenue | D3: 67 | J3: Banking & Financial Services | K3: 9 | L3: 8 | M3: 10 | N3: 10 | O3: 9 | P3: 8 | Q3: =$K$11*K3+$L$11*L3+$M$11*M3+$N$11*N3+$O$11*O3+$P$11*P3 -> 9.1 | R3: =Q3/$Q$10 -> 0.15294118 | S3: =80*R3 -> 12.235294
B4: Expenses | D4: 18 | J4: Power & Utilities | K4: 10 | L4: 10 | M4: 8 | N4: 8 | O4: 9 | P4: 7 | Q4: =$K$11*K4+$L$11*L4+$M$11*M4+$N$11*N4+$O$11*O4+$P$11*P4 -> 9 | R4: =Q4/$Q$10 -> 0.1512605 | S4: =80*R4 -> 12.10084
B5: Savings | D5: =D3-D4 -> 49 | J5: Capital Goods & Infrastructure | K5: 9 | L5: 10 | M5: 8 | N5: 9 | O5: 9 | P5: 8 | Q5: =$K$11*K5+$L$11*L5+$M$11*M5+$N$11*N5+$O$11*O5+$P$11*P5 -> 8.95 | R5: =Q5/$Q$10 -> 0.15042017 | S5: =80*R5 -> 12.033613
J6: Information Technology | K6: 8 | L6: 6 | M6: 10 | N6: 9 | O6: 9 | P6: 8 | Q6: =$K$11*K6+$L$11*L6+$M$11*M6+$N$11*N6+$O$11*O6+$P$11*P6 -> 8.3 | R6: =Q6/$Q$10 -> 0.1394958 | S6: =80*R6 -> 11.159664
B7: Portfolio Amount | D7: 80 | J7: Healthcare & Pharma | K7: 8 | L7: 8 | M7: 9 | N7: 9 | O7: 8 | P7: 8 | Q7: =$K$11*K7+$L$11*L7+$M$11*M7+$N$11*N7+$O$11*O7+$P$11*P7 -> 8.35 | R7: =Q7/$Q$10 -> 0.14033613 | S7: =80*R7 -> 11.226891
B8: Expectations of Client | J8: FMCG / Consumer Staples | K8: 7 | L8: 7 | M8: 9 | N8: 10 | O8: 8 | P8: 9 | Q8: =$K$11*K8+$L$11*L8+$M$11*M8+$N$11*N8+$O$11*O8+$P$11*P8 -> 8.1 | R8: =Q8/$Q$10 -> 0.13613445 | S8: =80*R8 -> 10.890756
B9: Home downpayment | D9: 50 | J9: Oil & Gas | K9: 7 | L9: 8 | M9: 9 | N9: 8 | O9: 7 | P9: 6 | Q9: =$K$11*K9+$L$11*L9+$M$11*M9+$N$11*N9+$O$11*O9+$P$11*P9 -> 7.7 | R9: =Q9/$Q$10 -> 0.12941176 | S9: =80*R9 -> 10.352941
B10: Home full payment | D10: 300 | Q10: =SUM(Q3:Q9) -> 59.5
B11: Children Future | D11: 200 | J11: Weights | K11: 0.25 | L11: 0.2 | M11: 0.2 | N11: 0.15 | O11: 0.15 | P11: 0.05
B12: Savings | D12: 150
B14: Total wealth at the end of 2033 | D14: =D10+D11+D12 -> 650 | J14: Stock | K14: Sector | L14: Cap
B15: Fixed savings from them | D15: =8*D5 -> 392 | J15: HDFC | K15: Banking & Financial Services | L15: LAR
B16: Final output they want from investments | D16: =D14-D15+D9 -> 308 | J16: ICICI | K16: Banking & Financial Services | L16: LAR
B17: CAGR | D17: =((D16/D7)^(1/8))-1 -> 0.18353905 | E17: the average growth rate at which our investments should grow our outputs | J17: TCS | K17: Information Technology Services | L17: LAR
J18: Infosys | K18: Information Technology Services | L18: LAR
J19: Power Grid | K19: Power Transmission & Utilities | L19: LAR
J20: Reliance Industries | K20: Energy, Oil & Gas | L20: LAR
J21: ITC | K21: FMCG (Consumer Staples) | L21: LAR
J22: Persistent Sys | K22: Digital Engineering & IT Services | L22: MID
J23: Cummins ind | K23: Capital Goods & Industrial Engineering | L23: MID
J24: Tata Elxsi | K24: Engineering R&D / Automotive Software | L24: MID
J25: ideaForge | K25: Defence & Drone Technology | L25: SMA
J26: Neuland Laborataries | K26: Pharmaceuticals (APIs & Specialty Pharma) | L26: SMA
J27: HBL Engineering | K27: Railway Electronics & Defence Systems | L27: SMA
J28: Kirloskar oil | K28: Industrial Engineering & Power Equipment | L28: SMA
J29: Nuvama Wealth management | K29: Financial Services & Wealth Management | L29: SMA

Sheet Stock Allocation Model
B1: Company | C1: Sales CAGR (5Y) | D1: Score | E1: Profit CAGR (5Y) | F1: Score | G1: ROE | H1: Score | I1: ROCE | J1: Score | K1: Debt/Equity | L1: Score | M1: Stock CAGR (10Y) | N1: Score | O1: Final Score | P1: Current Price | Q1: Weighted Score (Cap Wise) | R1: Cap wise Distribution | S1: Allocation (%)
B2: HDFC Bank | C2: 0.2208 | D2: 13 | E2: 0.1904 | F2: 14 | G2: 0.1378 | H2: 5 | I2: 0.0704 | J2: 2 | K2: 6.34 | L2: 10* | M2: 0.1266 | N2: 8 | O2: 52 | P2: 1008 | Q2: =O2/SUM($O$2:$O$8) -> 0.14168937 | R2: =$M$20 -> 0.45 | S2: =R2*Q2*$L$25 -> 0.058659401
B3: ICICI Bank | C3: 0.1697 | D3: 11 | E3: 0.2414 | F3: 17 | G3: 0.161 | H3: 8 | I3: 0.072 | J3: 2 | K3: 5.69 | L3: 10* | M3: 0.1965 | N3: 11 | O3: 59 | P3: 1462 | Q3: =O3/SUM($O$2:$O$8) -> 0.16076294 | R3: =$M$20 -> 0.45 | S3: =R3*Q3*$L$25 -> 0.066555858
B4: TCS | C4: 0.1022 | D4: 8 | E4: 0.0945 | F4: 6 | G4: 0.518 | H4: 15 | I4: 0.6303 | J4: 20 | K4: 0.11 | L4: 9 | M4: 0.1061 | N4: 8 | O4: 66 | P4: 3442 | Q4: =O4/SUM($O$2:$O$8) -> 0.17983651 | R4: =$M$20 -> 0.45 | S4: =R4*Q4*$L$25 -> 0.074452316
B5: Infosys | C5: 0.122 | D5: 8 | E5: 0.0929 | F5: 6 | G5: 0.319 | H5: 15 | I5: 0.4 | J5: 17 | K5: 0.1 | L5: 9 | M5: 0.1157 | N5: 8 | O5: 63 | P5: 1640 | Q5: =O5/SUM($O$2:$O$8) -> 0.17166213 | R5: =$M$20 -> 0.45 | S5: =R5*Q5*$L$25 -> 0.07106812
B6: Power Grid Corporation | C6: 0.0335 | D6: 2 | E6: 0.0435 | F6: 2 | G6: 0.165 | H6: 8 | I6: 0.0974 | J6: 2 | K6: 1.47 | L6: 3 | M6: 0.1197 | N6: 8 | O6: 25 | P6: 288 | Q6: =O6/SUM($O$2:$O$8) -> 0.068119891 | R6: =$M$20 -> 0.45 | S6: =R6*Q6*$L$25 -> 0.028201635
B7: Reliance Industries | C7: 0.1776 | D7: 11 | E7: 0.1198 | F7: 10 | G7: 0.0891 | H7: 2 | I7: 0.103 | J7: 6 | K7: 0.45 | L7: 7 | M7: 0.1985 | N7: 11 | O7: 47 | P7: 1527 | Q7: =O7/SUM($O$2:$O$8) -> 0.1280654 | R7: =$M$20 -> 0.45 | S7: =R7*Q7*$L$25 -> 0.053019074
B8: ITC | C8: 0.0987 | D8: 5 | E8: 0.0962 | F8: 6 | G8: 0.293 | H8: 13 | I8: 0.389 | J8: 17 | K8: 0.03 | L8: 9 | M8: 0.0596 | N8: 5 | O8: 55 | P8: 418 | Q8: =O8/SUM($O$2:$O$8) -> 0.14986376 | R8: =$M$20 -> 0.45 | S8: =R8*Q8*$L$25 -> 0.062043597
B9: Persistent Systems | C9: 0.2863 | D9: 15 | E9: 0.3591 | F9: 20 | G9: 0.273 | H9: 13 | I9: 0.344 | J9: 17 | K9: 0.06 | L9: 9 | M9: 0.3213 | N9: 20 | O9: 94 | P9: 6010 | Q9: =O9/SUM($O$9:$O$11) -> 0.3715415 | R9: =$M$21 -> 0.3 | S9: =R9*Q9*$L$25 -> 0.10254545
B10: Cummins India | C10: 0.2273 | D10: 13 | E10: 0.3082 | F10: 20 | G10: 0.302 | H10: 13 | I10: 0.3905 | J10: 20 | K10: 0 | L10: 10 | M10: 0.1665 | N10: 11 | O10: 87 | P10: 3337 | Q10: =O10/SUM($O$9:$O$11) -> 0.34387352 | R10: =$M$21 -> 0.3 | S10: =R10*Q10*$L$25 -> 0.094909091
B11: Tata Elxsi | C11: 0.1552 | D11: 11 | E11: 0.1375 | F11: 10 | G11: 0.236 | H11: 11 | I11: 0.3 | J11: 17 | K11: 0.05 | L11: 9 | M11: 0.2212 | N11: 14 | O11: 72 | P11: 6345 | Q11: =O11/SUM($O$9:$O$11) -> 0.28458498 | R11: =$M$21 -> 0.3 | S11: =R11*Q11*$L$25 -> 0.078545455
B12: Data Patterns | C12: 0.3279 | D12: 15 | E12: 0.3756 | F12: 20 | G12: 0.169 | H12: 8 | I12: 0.233 | J12: 14 | K12: 0 | L12: 10 | M12: 0.1472 | N12: 8 | O12: 75 | P12: 2824 | Q12: =O12/SUM($O$12:$O$16) -> 0.1875 | R12: =$M$22 -> 0.25 | S12: =R12*Q12*$L$25 -> 0.043125
B13: Neuland Laboratories | C13: 0.1664 | D13: 11 | E13: 0.3874 | F13: 20 | G13: 0.214 | H13: 11 | I13: 0.266 | J13: 14 | K13: 0.16 | L13: 9 | M13: 0.3224 | N13: 20 | O13: 85 | P13: 12120 | Q13: =O13/SUM($O$12:$O$16) -> 0.2125 | R13: =$M$22 -> 0.25 | S13: =R13*Q13*$L$25 -> 0.048875
B14: HBL Engineering | C14: 0.2935 | D14: 15 | E14: 1.1777 | F14: 20 | G14: 0.453 | H14: 15 | I14: 0.584 | J14: 20 | K14: 0.03 | L14: 9 | M14: 0.3163 | N14: 20 | O14: 99 | P14: 630 | Q14: =O14/SUM($O$12:$O$16) -> 0.2475 | R14: =$M$22 -> 0.25 | S14: =R14*Q14*$L$25 -> 0.056925
B15: Kirloskar Oil Engines | C15: 0.185 | D15: 11 | E15: 0.2535 | F15: 17 | G15: 0.177 | H15: 8 | I15: 0.147 | J15: 6 | K15: 1.48 | L15: 3 | M15: 0.1285 | N15: 8 | O15: 53 | P15: 860 | Q15: =O15/SUM($O$12:$O$16) -> 0.1325 | R15: =$M$22 -> 0.25 | S15: =R15*Q15*$L$25 -> 0.030475
B16: Nuvama Wealth Management** | C16: 0.2732 | D16: 15 | E16: 0.5869 | F16: 20 | G16: 0.274 | H16: 13 | I16: 0.175 | J16: 10 | K16: 2.8 | L16: 10* | M16: 0.5092 | N16: 20 | O16: 88 | P16: 1658 | Q16: =O16/SUM($O$12:$O$16) -> 0.22 | R16: =$M$22 -> 0.25 | S16: =R16*Q16*$L$25 -> 0.0506
B19: Notes | M19: Ideal Case Allocation
L20: Large Cap | M20: 0.45
B21: Scoring Methodology | L21: Medium Cap | M21: 0.3
L22: Small Cap | M22: 0.25
B23: Sales CAGR (5Y) evaluates long-term business growth.
B24: Profit CAGR (5Y) measures earnings growth and receives a higher weight because shareholder value is ultimately driven by profits.
B25: ROE measures returns generated for shareholders. | K25: Equity | L25: 0.92
B26: ROCE measures capital efficiency and receives a higher weight than ROE because it evaluates returns generated from total capital employed. | K26: Gold ETF(commodity) | L26: 0.05
B27: Debt-to-Equity measures financial stability. Lower debt is preferred. | K27: Target Maturity Debt Fund / Government Securities | L27: 0.03
B28: Historical Stock CAGR (2015–2025) measures long-term shareholder wealth creation and serves as a market validation metric.
B30: Special Cases
B32: 1. Banks & Financial Services (HDFC Bank, ICICI Bank, Nuvama Wealth Management):
B33: Debt-to-Equity is not directly comparable with non-financial companies because deposits and borrowings are integral to their business models.
B34: Therefore, they were awarded the full Debt score (10/10), and greater emphasis was placed on profitability and historical performance.
B35: 2. Nuvama Wealth Management:
B36: Since the company was listed in 2023, the Stock CAGR has been calculated using the available listing period instead of a full 10-year history.
B37: This limitation should be clearly mentioned in the report.
B38: 3. Portfolio Allocation:
B39: Final scores are not used to compare Large-, Mid-, and Small-cap companies directly.
B40: Companies are first grouped by market capitalization, and scores are then used to rank companies within each category before allocating capital according to the predefined Large-, Mid-, and Small-cap weights.

Sheet Adjustment Factor
B1: Company | C1: Historical CAGR | D1: Adjustment Factor | E1: Rationale
B2: HDFC Bank | C2: 0.1266 | D2: 1.05 | E2: Strong credit growth, digital banking expansion, stable valuation, long runway for financialization.
B3: ICICI Bank | C3: 0.1965 | D3: 0.95 | E3: Excellent fundamentals but already rerated significantly; moderate valuation compression risk.
B4: TCS | C4: 0.1061 | D4: 1 | E4: AI, cloud transformation and digital engineering expected to support steady long-term growth.
B5: Infosys | C5: 0.1157 | D5: 1.08 | E5: Continued enterprise digital transformation with moderate upside from AI adoption.
B6: Power Grid | C6: 0.1197 | D6: 1.05 | E6: Grid modernization, renewable integration and transmission capex provide visibility.
B7: Reliance Industries | C7: 0.1985 | D7: 0.95 | E7: Large diversified conglomerate; future growth balanced by already high expectations.
B8: ITC | C8: 0.0596 | D8: 1.15 | E8: FMCG expansion, hotels demerger and stronger non-cigarette business improve outlook.
B9: Persistent Systems | C9: 0.3213 | D9: 0.84 | E9: AI and digital engineering remain strong, but sustaining 30%+ CAGR for another 8 years is unlikely.
B10: Cummins India | C10: 0.1665 | D10: 1.08 | E10: Manufacturing capex cycle, power backup demand and export opportunities remain favourable.
B11: Tata Elxsi | C11: 0.2212 | D11: 0.9 | E11: Strong EV/software theme but premium valuation suggests modest moderation.
B12: Data Patterns | C12: 0.1472 | D12: 1.15 | E12: Defence indigenisation, increasing defence spending and export potential.
B13: Neuland Laboratories | C13: 0.3224 | D13: 0.8 | E13: Specialty pharma has excellent long-term prospects, but historical outperformance is unlikely to repeat fully.
... B18: Bharat Bond ETF | C18: 0.0756 | D18: 1 | E18: Fixed-income instrument; returns largely driven by coupon yield and interest rate movements.

Sheet Ideal Scenario (2025-2033)
C1: Investment amount | D1: 8000000 | F1: Required CAGR | G1: 0.1835 | J1: Investemnt Horizon | K1: 8 | M1: Minimum Required Returns | N1: 30800000
C2: Stock | D2: Sector | E2: Allocation (%) | F2: Investment Amount (₹) | G2: CAGR (Past 10Y) | H2: Current Price | I2: Adjustment Factor(for 8 years) | J2: Expected CAGR | K2: Projected Value (2033) | L2: Shares Purchased | M2: Projected Returns (₹) | N2: Beta (3y)
C3: HDFC Bank | D3: Banking & Financial Services | E3: =IFERROR('Stock Allocation Model'!S2,0) -> 0.058659401 | F3: =$D$1*E3 -> 469275.2 | G3: =IFERROR('Stock Allocation Model'!M2,0) -> 0.1266 | H3: =IFERROR('Stock Allocation Model'!P2,0) -> 1008 | I3: =IFERROR('Adjustment Factor'!D2,0) -> 1.05 | J3: =G3*I3 -> 0.13293 | K3: =H3*(1+J3)^$K$1 -> 2735.8051 | L3: =F3/H3 -> 465.5508 | M3: =L3*K3 -> 1273656.2 | N3: 1
C4: ICICI Bank | D4: Banking & Financial Services | E4: =IFERROR('Stock Allocation Model'!S3,0) -> 0.066555858 | F4: =$D$1*E4 -> 532446.87 | G4: =IFERROR('Stock Allocation Model'!M3,0) -> 0.1965 | H4: =IFERROR('Stock Allocation Model'!P3,0) -> 1462 | I4: =IFERROR('Adjustment Factor'!D3,0) -> 0.95 | J4: =G4*I4 -> 0.186675 | K4: =H4*(1+J4)^$K$1 -> 5749.1245 | L4: =F4/H4 -> 364.19074 | M4: =L4*K4 -> 2093777.9 | N4: 0.9
C5: Tata Consultancy Services (TCS) | D5: Information Technology Services | E5: =IFERROR('Stock Allocation Model'!S4,0) -> 0.074452316 | F5: =$D$1*E5 -> 595618.53 | G5: =IFERROR('Stock Allocation Model'!M4,0) -> 0.1061 | H5: =IFERROR('Stock Allocation Model'!P4,0) -> 3442 | I5: =IFERROR('Adjustment Factor'!D4,0) -> 1 | J5: =G5*I5 -> 0.1061 | K5: =H5*(1+J5)^$K$1 -> 7711.982 | L5: =F5/H5 -> 173.04431 | M5: =L5*K5 -> 1334514.6 | N5: 0.7
C6: Infosys | D6: Information Technology Services | E6: =IFERROR('Stock Allocation Model'!S5,0) -> 0.07106812 | F6: =$D$1*E6 -> 568544.96 | G6: =IFERROR('Stock Allocation Model'!M5,0) -> 0.1157 | H6: =IFERROR('Stock Allocation Model'!P5,0) -> 1640 | I6: =IFERROR('Adjustment Factor'!D5,0) -> 1.08 | J6: =G6*I6 -> 0.124956 | K6: =H6*(1+J6)^$K$1 -> 4206.5702 | L6: =F6/H6 -> 346.67376 | M6: =L6*K6 -> 1458307.5 | N6: 0.8
C7: Power Grid Corporation | D7: Power Transmission & Utilities | E7: =IFERROR('Stock Allocation Model'!S6,0) -> 0.028201635 | F7: =$D$1*E7 -> 225613.08 | G7: =IFERROR('Stock Allocation Model'!M6,0) -> 0.1197 | H7: =IFERROR('Stock Allocation Model'!P6,0) -> 288 | I7: =IFERROR('Adjustment Factor'!D6,0) -> 1.05 | J7: =G7*I7 -> 0.125685 | K7: =H7*(1+J7)^$K$1 -> 742.55311 | L7: =F7/H7 -> 783.37875 | M7: =L7*K7 -> 581700.32 | N7: 0.9
C8: Reliance Industries | D8: Energy, Oil & Gas | E8: =IFERROR('Stock Allocation Model'!S7,0) -> 0.053019074 | F8: =$D$1*E8 -> 424152.59 | G8: =IFERROR('Stock Allocation Model'!M7,0) -> 0.1985 | H8: =IFERROR('Stock Allocation Model'!P7,0) -> 1527 | I8: =IFERROR('Adjustment Factor'!D7,0) -> 0.95 | J8: =G8*I8 -> 0.188575 | K8: =H8*(1+J8)^$K$1 -> 6082.0749 | L8: =F8/H8 -> 277.76856 | M8: =L8*K8 -> 1689409.2 | N8: 1
C9: ITC | D9: FMCG (Consumer Staples) | E9: =IFERROR('Stock Allocation Model'!S8,0) -> 0.062043597 | F9: =$D$1*E9 -> 496348.77 | G9: =IFERROR('Stock Allocation Model'!M8,0) -> 0.0596 | H9: =IFERROR('Stock Allocation Model'!P8,0) -> 418 | I9: =IFERROR('Adjustment Factor'!D8,0) -> 1.15 | J9: =G9*I9 -> 0.06854 | K9: =H9*(1+J9)^$K$1 -> 710.39935 | L9: =F9/H9 -> 1187.4373 | M9: =L9*K9 -> 843554.66 | N9: 0.6
C10: Persistent Systems | D10: Digital Engineering & IT Services | E10: =IFERROR('Stock Allocation Model'!S9,0) -> 0.10254545 | F10: =$D$1*E10 -> 820363.64 | G10: =IFERROR('Stock Allocation Model'!M9,0) -> 0.3213 | H10: =IFERROR('Stock Allocation Model'!P9,0) -> 6010 | I10: =IFERROR('Adjustment Factor'!D9,0) -> 0.84 | J10: =G10*I10 -> 0.269892 | K10: =H10*(1+J10)^$K$1 -> 40645.154 | L10: =F10/H10 -> 136.49977 | M10: =L10*K10 -> 5548054.3 | N10: 0.9
C11: Cummins India | D11: Capital Goods & Industrial Engineering | E11: =IFERROR('Stock Allocation Model'!S10,0) -> 0.094909091 | F11: =$D$1*E11 -> 759272.73 | G11: =IFERROR('Stock Allocation Model'!M10,0) -> 0.1665 | H11: =IFERROR('Stock Allocation Model'!P10,0) -> 3337 | I11: =IFERROR('Adjustment Factor'!D10,0) -> 1.08 | J11: =G11*I11 -> 0.17982 | K11: =H11*(1+J11)^$K$1 -> 12528.014 | L11: =F11/H11 -> 227.53153 | M11: =L11*K11 -> 2850518.3 | N11: 1.1
C12: Tata Elxsi | D12: Engineering R&D / Automotive Software | E12: =IFERROR('Stock Allocation Model'!S11,0) -> 0.078545455 | F12: =$D$1*E12 -> 628363.64 | G12: =IFERROR('Stock Allocation Model'!M11,0) -> 0.2212 | H12: =IFERROR('Stock Allocation Model'!P11,0) -> 6345 | I12: =IFERROR('Adjustment Factor'!D11,0) -> 0.9 | J12: =G12*I12 -> 0.19908 | K12: =H12*(1+J12)^$K$1 -> 27115.455 | L12: =F12/H12 -> 99.032882 | M12: =L12*K12 -> 2685321.7 | N12: 0.9
C13: Data Patterns | D13: Defence & Drone Technology | E13: =IFERROR('Stock Allocation Model'!S12,0) -> 0.043125 | F13: =$D$1*E13 -> 345000 | G13: =IFERROR('Stock Allocation Model'!M12,0) -> 0.1472 | H13: =IFERROR('Stock Allocation Model'!P12,0) -> 2824 | I13: =IFERROR('Adjustment Factor'!D12,0) -> 1.15 | J13: =G13*I13 -> 0.16928 | K13: =H13*(1+J13)^$K$1 -> 9867.6301 | L13: =F13/H13 -> 122.16714 | M13: =L13*K13 -> 1205500.1 | N13: 1.1
C14: Neuland Laboratories | D14: Pharmaceuticals (APIs & Specialty Pharma) | E14: =IFERROR('Stock Allocation Model'!S13,0) -> 0.048875 | F14: =$D$1*E14 -> 391000 | G14: =IFERROR('Stock Allocation Model'!M13,0) -> 0.3224 | H14: =IFERROR('Stock Allocation Model'!P13,0) -> 12120 | I14: =IFERROR('Adjustment Factor'!D13,0) -> 0.8 | J14: =G14*I14 -> 0.25792 | K14: =H14*(1+J14)^$K$1 -> 75984.813 | L14: =F14/H14 -> 32.260726 | M14: =L14*K14 -> 2451325.2 | N14: 0.8
... C17: Nuvama Wealth Management | D17: Financial Services & Wealth Management | E17: =IFERROR('Stock Allocation Model'!S16,0) -> 0.0506 | F17: =$D$1*E17 -> 404800 | G17: =IFERROR('Stock Allocation Model'!M16,0) -> 0.5092 | H17: =IFERROR('Stock Allocation Model'!P16,0) -> 1658 | I17: =IFERROR('Adjustment Factor'!D16,0) -> 0.7 | J17: =G17*I17 -> 0.35644 | K17: =H17*(1+J17)^$K$1 -> 19001.559 | L17: =F17/H17 -> 244.14958 | M17: =L17*K17 -> 4639222.6 | N17: 1.4
C18: Nippon India ETF Gold BeES | D18: Commodity | E18: 0.05 | F18: =$D$1*E18 -> 400000 | G18: 0.1387 | H18: 81 | I18: =IFERROR('Adjustment Factor'!D17,0) -> 0.95 | J18: =G18*I18 -> 0.131765 | K18: =H18*(1+J18)^$K$1 -> 218.03946 | L18: =F18/H18 -> 4938.2716 | M18: =L18*K18 -> 1076738.1 | N18: 0.1
C19: Bharat Bond ETF April 2030 | D19: Fixed Income (Debt Instruments) | E19: 0.03 | F19: =$D$1*E19 -> 240000 | G19: 0.0756 | H19: 1536 | I19: =IFERROR('Adjustment Factor'!D18,0) -> 1 | J19: =G19*I19 -> 0.0756 | K19: =H19*(1+J19)^$K$1 -> 2751.6777 | L19: =F19/H19 -> 156.25 | M19: =L19*K19 -> 429949.64 | N19: 0.48
C20: Total | E20: =SUM(E3:E19) -> 1 | F20: =SUM(F3:F19) -> 8000000 | M20: =SUM(M3:M19) -> 33183519
C22: Risk Free Rate (Rf) | D22: 0.06 | M22: Large Cap
C23: Market Returns Rate (Rm) | D23: 0.107 | M23: Medium Cap
C24: Projected Returns at the end of 2033 | D24: =M20 -> 33183519 | M24: Small Cap
C25: Beta of the portfolio | D25: =SUMPRODUCT(E3:E19,N3:N19) -> 0.89748681
C26: Portfolio Returns (Rp) | D26: =SUMPRODUCT(E3:E19,J3:J19) -> 0.17905019
C27: Sigma | D27: =_xlfn.STDEV.P((J3:J19)) -> 0.072188946
C28: Sharpe Ratio | D28: =(D26-D22)/D27 -> 1.6491472
C29: Treynor Ratio | D29: =(D26-D22)/D25 -> 0.13264841
C30: Jensen Alpha | D30: =D26-(D22+(D23-D22)*D25) -> 0.076868315
C37: Notes
C39: Portfolio Construction Methodology
C40: 1. The portfolio has been constructed assuming an initial investment of ₹80,00,000 in June 2025 with an investment horizon of 8 years.
C41: 2. The investment objective is to achieve a minimum portfolio CAGR of 18.35% to meet the client's long-term financial goals while maintaining an appropriate level of diversification and risk.
C42: 3. Asset allocation consists of:
C43: Equity: 92%
C44: Gold ETF: 5%
C45: Fixed Income: 3%
C46: 4. Equity allocation was distributed across Large-, Mid-, and Small-cap companies using a quantitative company scoring model based on:
C47: Sales CAGR (5Y)
C48: Return on Capital Employed (ROCE) | D48: Profit CAGR (5Y) | E48: Return on Equity (ROE)
C49: 5. Capital was allocated to companies after normalizing the scores within each market-cap category to maintain diversification while rewarding fundamentally stronger businesses. | D49: Debt-to-Equity Ratio | F49: Historical Stock CAGR (10Y)
C50: 6. Historical financial metrics were obtained from Screener, while 3-Year Beta values were sourced from Trendlyne to maintain consistency in risk estimation.
...

Sheet Phase 1 (Jun 2025 - Apr 2028)
B1: Investment amount | C1: 8000000 | E1: Required CAGR | F1: 0.1835 | I1: Investemnt Horizon | J1: 8 | L1: Minimum Required Returns | M1: 30800000
B2: Stock | C2: Sector | D2: Allocation (%) | E2: Investment Amount (₹) | F2: CAGR (Past 10Y) | G2: Current Price | H2: Adjustment Factor | I2: Expected CAGR | J2: Projected Value (Apr 2028) | K2: Shares Purchased | L2: Projected Returns (₹) | M2: Beta (3y)
B3: HDFC Bank | C3: Banking & Financial Services | D3: =IFERROR('Ideal Scenario (2025-2033)'!E3,0) -> 0.058659401 | E3: =IFERROR('Ideal Scenario (2025-2033)'!F3,0) -> 469275.2 | F3: =IFERROR('Ideal Scenario (2025-2033)'!G3,0) -> 0.1266 | G3: =IFERROR('Ideal Scenario (2025-2033)'!H3,0) -> 1008 | H3: =IFERROR('Ideal Scenario (2025-2033)'!I3,0) -> 1.05 | I3: =H3*F3 -> 0.13293 | J3: =G3*(1+I3)^2.91 -> 1449.4108 | K3: 465.5508 | L3: =K3*J3 -> 674774.34 | M3: 1
B4: ICICI Bank | C4: Banking & Financial Services | D4: =IFERROR('Ideal Scenario (2025-2033)'!E4,0) -> 0.066555858 | E4: =IFERROR('Ideal Scenario (2025-2033)'!F4,0) -> 532446.87 | F4: =IFERROR('Ideal Scenario (2025-2033)'!G4,0) -> 0.1965 | G4: =IFERROR('Ideal Scenario (2025-2033)'!H4,0) -> 1462 | H4: =IFERROR('Ideal Scenario (2025-2033)'!I4,0) -> 0.95 | I4: =H4*F4 -> 0.186675 | J4: =G4*(1+I4)^2.91 -> 2405.7633 | K4: 364.19074 | L4: =K4*J4 -> 876156.71 | M4: 0.9
B5: Tata Consultancy Services (TCS) | C5: Information Technology Services | D5: =IFERROR('Ideal Scenario (2025-2033)'!E5,0) -> 0.074452316 | E5: =IFERROR('Ideal Scenario (2025-2033)'!F5,0) -> 595618.53 | F5: =IFERROR('Ideal Scenario (2025-2033)'!G5,0) -> 0.1061 | G5: =IFERROR('Ideal Scenario (2025-2033)'!H5,0) -> 3442 | H5: =IFERROR('Ideal Scenario (2025-2033)'!I5,0) -> 1 | I5: =H5*F5 -> 0.1061 | J5: =G5*(1+I5)^2.91 -> 4615.8591 | K5: 173.04431 | L5: =K5*J5 -> 798748.18 | M5: 0.7
B6: Infosys | C6: Information Technology Services | D6: =IFERROR('Ideal Scenario (2025-2033)'!E6,0) -> 0.07106812 | E6: =IFERROR('Ideal Scenario (2025-2033)'!F6,0) -> 568544.96 | F6: =IFERROR('Ideal Scenario (2025-2033)'!G6,0) -> 0.1157 | G6: =IFERROR('Ideal Scenario (2025-2033)'!H6,0) -> 1640 | H6: =IFERROR('Ideal Scenario (2025-2033)'!I6,0) -> 1.08 | I6: =H6*F6 -> 0.124956 | J6: =G6*(1+I6)^2.91 -> 2310.193 | K6: 346.67376 | L6: =K6*J6 -> 800883.27 | M6: 0.8
B7: Power Grid Corporation | C7: Power Transmission & Utilities | D7: =IFERROR('Ideal Scenario (2025-2033)'!E7,0) -> 0.028201635 | E7: =IFERROR('Ideal Scenario (2025-2033)'!F7,0) -> 225613.08 | F7: =IFERROR('Ideal Scenario (2025-2033)'!G7,0) -> 0.1197 | G7: =IFERROR('Ideal Scenario (2025-2033)'!H7,0) -> 288 | H7: =IFERROR('Ideal Scenario (2025-2033)'!I7,0) -> 1.05 | I7: =H7*F7 -> 0.125685 | J7: =G7*(1+I7)^2.91 -> 406.45793 | K7: 783.37875 | L7: =K7*J7 -> 318410.51 | M7: 0.9
B8: Reliance Industries | C8: Energy, Oil & Gas | D8: =IFERROR('Ideal Scenario (2025-2033)'!E8,0) -> 0.053019074 | E8: =IFERROR('Ideal Scenario (2025-2033)'!F8,0) -> 424152.59 | F8: =IFERROR('Ideal Scenario (2025-2033)'!G8,0) -> 0.1985 | G8: =IFERROR('Ideal Scenario (2025-2033)'!H8,0) -> 1527 | H8: =IFERROR('Ideal Scenario (2025-2033)'!I8,0) -> 0.95 | I8: =H8*F8 -> 0.188575 | J8: =G8*(1+I8)^2.91 -> 2524.4479 | K8: 277.76856 | L8: =K8*J8 -> 701212.26 | M8: 1
B9: ITC | C9: FMCG (Consumer Staples) | D9: =IFERROR('Ideal Scenario (2025-2033)'!E9,0) -> 0.062043597 | E9: =IFERROR('Ideal Scenario (2025-2033)'!F9,0) -> 496348.77 | F9: =IFERROR('Ideal Scenario (2025-2033)'!G9,0) -> 0.0596 | G9: =IFERROR('Ideal Scenario (2025-2033)'!H9,0) -> 418 | H9: =IFERROR('Ideal Scenario (2025-2033)'!I9,0) -> 1.15 | I9: =H9*F9 -> 0.06854 | J9: =G9*(1+I9)^2.91 -> 506.94105 | K9: 1187.4373 | L9: =K9*J9 -> 601960.7 | M9: 0.6
B10: Persistent Systems | C10: Digital Engineering & IT Services | D10: =IFERROR('Ideal Scenario (2025-2033)'!E10,0) -> 0.10254545 | E10: =IFERROR('Ideal Scenario (2025-2033)'!F10,0) -> 820363.64 | F10: =IFERROR('Ideal Scenario (2025-2033)'!G10,0) -> 0.3213 | G10: =IFERROR('Ideal Scenario (2025-2033)'!H10,0) -> 6010 | H10: 0.95 | I10: =H10*F10 -> 0.305235 | J10: =G10*(1+I10)^2.91 -> 13047.54 | K10: 136.49977 | L10: =K10*J10 -> 1780986.2 | M10: 0.9
B11: Cummins India | C11: Capital Goods & Industrial Engineering | D11: =IFERROR('Ideal Scenario (2025-2033)'!E11,0) -> 0.094909091 | E11: =IFERROR('Ideal Scenario (2025-2033)'!F11,0) -> 759272.73 | F11: =IFERROR('Ideal Scenario (2025-2033)'!G11,0) -> 0.1665 | G11: =IFERROR('Ideal Scenario (2025-2033)'!H11,0) -> 3337 | H11: =IFERROR('Ideal Scenario (2025-2033)'!I11,0) -> 1.08 | I11: =H11*F11 -> 0.17982 | J11: =G11*(1+I11)^2.91 -> 5399.3322 | K11: 227.53153 | L11: =K11*J11 -> 1228518.3 | M11: 1.1
B12: Tata Elxsi | C12: Engineering R&D / Automotive Software | D12: =IFERROR('Ideal Scenario (2025-2033)'!E12,0) -> 0.078545455 | E12: =IFERROR('Ideal Scenario (2025-2033)'!F12,0) -> 628363.64 | F12: =IFERROR('Ideal Scenario (2025-2033)'!G12,0) -> 0.2212 | G12: =IFERROR('Ideal Scenario (2025-2033)'!H12,0) -> 6345 | H12: 1 | I12: =H12*F12 -> 0.2212 | J12: =G12*(1+I12)^2.91 -> 11349.617 | K12: 99.032882 | L12: =K12*J12 -> 1123985.3 | M12: 0.9
B13: Data Patterns | C13: Defence & Drone Technology | D13: =IFERROR('Ideal Scenario (2025-2033)'!E13,0) -> 0.043125 | E13: =IFERROR('Ideal Scenario (2025-2033)'!F13,0) -> 345000 | F13: =IFERROR('Ideal Scenario (2025-2033)'!G13,0) -> 0.1472 | G13: =IFERROR('Ideal Scenario (2025-2033)'!H13,0) -> 2824 | H13: 1.25 | I13: =H13*F13 -> 0.184 | J13: =G13*(1+I13)^2.91 -> 4616.5564 | K13: 122.16714 | L13: =K13*J13 -> 563991.49 | M13: 1.1
B14: Neuland Laboratories | C14: Pharmaceuticals (APIs & Specialty Pharma) | D14: =IFERROR('Ideal Scenario (2025-2033)'!E14,0) -> 0.048875 | E14: =IFERROR('Ideal Scenario (2025-2033)'!F14,0) -> 391000 | F14: =IFERROR('Ideal Scenario (2025-2033)'!G14,0) -> 0.3224 | G14: =IFERROR('Ideal Scenario (2025-2033)'!H14,0) -> 12120 | H14: 0.9 | I14: =H14*F14 -> 0.29016 | J14: =G14*(1+I14)^2.91 -> 25437.558 | K14: 32.260726 | L14: =K14*J14 -> 820634.09 | M14: 0.8
B15: HBL Engineering | C15: Railway Electronics & Defence Systems | D15: =IFERROR('Ideal Scenario (2025-2033)'!E15,0) -> 0.056925 | E15: =IFERROR('Ideal Scenario (2025-2033)'!F15,0) -> 455400 | F15: =IFERROR('Ideal Scenario (2025-2033)'!G15,0) -> 0.3163 | G15: =IFERROR('Ideal Scenario (2025-2033)'!H15,0) -> 630 | H15: 0.9 | I15: =H15*F15 -> 0.28467 | J15: =G15*(1+I15)^2.91 -> 1305.9425 | K15: 770.55838 | L15: =K15*J15 -> 1006304.9 | M15: 1.4
B16: Kirloskar Oil Engines | C16: Industrial Engineering & Power Equipment | D16: =IFERROR('Ideal Scenario (2025-2033)'!E16,0) -> 0.030475 | E16: =IFERROR('Ideal Scenario (2025-2033)'!F16,0) -> 243800 | F16: =IFERROR('Ideal Scenario (2025-2033)'!G16,0) -> 0.1285 | G16: =IFERROR('Ideal Scenario (2025-2033)'!H16,0) -> 860 | H16: =IFERROR('Ideal Scenario (2025-2033)'!I16,0) -> 1.05 | I16: =H16*F16 -> 0.134925 | J16: =G16*(1+I16)^2.91 -> 1242.9478 | K16: 283.48837 | L16: =K16*J16 -> 352361.25 | M16: 1
B17: Nuvama Wealth Management | C17: Financial Services & Wealth Management | D17: =IFERROR('Ideal Scenario (2025-2033)'!E17,0) -> 0.0506 | E17: =IFERROR('Ideal Scenario (2025-2033)'!F17,0) -> 404800 | F17: =IFERROR('Ideal Scenario (2025-2033)'!G17,0) -> 0.5092 | G17: =IFERROR('Ideal Scenario (2025-2033)'!H17,0) -> 1658 | H17: 0.9 | I17: =H17*F17 -> 0.45828 | J17: =G17*(1+I17)^2.91 -> 4970.0597 | K17: 244.14958 | L17: =K17*J17 -> 1213438 | M17: 1.4
B18: Nippon India ETF Gold BeES | C18: Commodity | D18: =IFERROR('Ideal Scenario (2025-2033)'!E18,0) -> 0.05 | E18: =IFERROR('Ideal Scenario (2025-2033)'!F18,0) -> 400000 | F18: =IFERROR('Ideal Scenario (2025-2033)'!G18,0) -> 0.1387 | G18: =IFERROR('Ideal Scenario (2025-2033)'!H18,0) -> 81 | H18: =IFERROR('Ideal Scenario (2025-2033)'!I18,0) -> 0.95 | I18: =H18*F18 -> 0.131765 | J18: =G18*(1+I18)^2.91 -> 116.12233 | K18: 4938.2716 | L18: =K18*J18 -> 573443.59 | M18: 0.1
B19: Bharat Bond ETF April 2030 | C19: Fixed Income (Debt Instruments) | D19: =IFERROR('Ideal Scenario (2025-2033)'!E19,0) -> 0.03 | E19: =IFERROR('Ideal Scenario (2025-2033)'!F19,0) -> 240000 | F19: =IFERROR('Ideal Scenario (2025-2033)'!G19,0) -> 0.0756 | G19: =IFERROR('Ideal Scenario (2025-2033)'!H19,0) -> 1536 | H19: =IFERROR('Ideal Scenario (2025-2033)'!I19,0) -> 1 | I19: =H19*F19 -> 0.0756 | J19: =G19*(1+I19)^2.91 -> 1898.8691 | K19: 156.25 | L19: =K19*J19 -> 296698.3 | M19: 0.48
B20: Total | D20: =SUM(D3:D19) -> 1 | E20: =SUM(E3:E19) -> 8000000 | L20: =SUM(L3:L19) -> 13732507
B22: Risk Free Rate (Rf) | C22: 0.06
B23: Market Returns Rate (Rm) | C23: 0.107 | L23: Large Cap
B24: Projected Returns at the end of Apr 2028 | C24: =L20 -> 13732507 | L24: Medium Cap
B25: Beta of the portfolio | C25: =SUMPRODUCT(D3:D19,M3:M19) -> 0.89748681 | L25: Small Cap
B26: Portfolio Returns (Rp) | C26: =SUMPRODUCT(D3:D19,I3:I19) -> 0.19501649
B27: Sigma | C27: =_xlfn.STDEV.P((I3:I19)) -> 0.096480888
B28: Sharpe Ratio | C28: =(C26-C22)/C27 -> 1.3994117
B29: Treynor Ratio | C29: =(C26-C22)/C25 -> 0.15043841
B30: Jensen Alpha | C30: =C26-(C22+(C23-C22)*C25) -> 0.092834606

Sheet Phase 2 (May 2028 - Dec 2030)
B1: Investment amount | C1: ='Phase 1 (Jun 2025 - Apr 2028)'!C24 -> 13732507 | F1: Required CAGR | G1: 0.1835 | J1: Investemnt Horizon | K1: 8 | M1: Minimum Required Returns | N1: 30800000
B2: Stock | C2: Sector | D2: Previous Allocation (%) | E2: Updated Allocation(%) | F2: Investment Amount (₹) | G2: CAGR (Past 10Y) | H2: Current Price (May 2028) | I2: Adjustment Factor | J2: Expected CAGR | K2: Projected Value (Dec 2030) | L2: Shares Purchased | M2: Projected Returns (at the end of Dec 2030) | N2: Beta (3y) | O2: Comment
B3: HDFC Bank | C3: Banking & Financial Services | D3: ='Phase 1 (Jun 2025 - Apr 2028)'!D3 -> 0.058659401 | E3: =D3 -> 0.058659401 | F3: =$C$1*E3 -> 805540.65 | G3: 0.1266 | H3: ='Phase 1 (Jun 2025 - Apr 2028)'!J3 -> 1449.4108 | I3: 1.1 | J3: =I3*G3 -> 0.13926 | K3: =H3*(1+J3)^2.67 -> 2052.9317 | L3: =F3/H3 -> 555.77112 | M3: =K3*L3 -> 1140960.1 | N3: 1 | O3: No major change
B4: ICICI Bank | C4: Banking & Financial Services | D4: ='Phase 1 (Jun 2025 - Apr 2028)'!D4 -> 0.066555858 | E4: =D4 -> 0.066555858 | F4: =$C$1*E4 -> 913978.82 | G4: 0.1965 | H4: ='Phase 1 (Jun 2025 - Apr 2028)'!J4 -> 2405.7633 | I4: 1.05 | J4: =I4*G4 -> 0.206325 | K4: =H4*(1+J4)^2.67 -> 3969.7453 | L4: =F4/H4 -> 379.9122 | M4: =K4*L4 -> 1508154.7 | N4: 0.9 | O4: No major change
B5: Tata Consultancy Services (TCS) | C5: Information Technology Services | D5: ='Phase 1 (Jun 2025 - Apr 2028)'!D5 -> 0.074452316 | E5: =D5 -> 0.074452316 | F5: =$C$1*E5 -> 1022417 | G5: 0.1061 | H5: ='Phase 1 (Jun 2025 - Apr 2028)'!J5 -> 4615.8591 | I5: 1 | J5: =I5*G5 -> 0.1061 | K5: =H5*(1+J5)^2.67 -> 6042.0397 | L5: =F5/H5 -> 221.50091 | M5: =K5*L5 -> 1338317.3 | N5: 0.7 | O5: No major change
B6: Infosys | C6: Information Technology Services | D6: ='Phase 1 (Jun 2025 - Apr 2028)'!D6 -> 0.07106812 | E6: =D6 -> 0.07106812 | F6: =$C$1*E6 -> 975943.48 | G6: 0.1157 | H6: ='Phase 1 (Jun 2025 - Apr 2028)'!J6 -> 2310.193 | I6: 1.08 | J6: =I6*G6 -> 0.124956 | K6: =H6*(1+J6)^2.67 -> 3163.5896 | L6: =F6/H6 -> 422.45106 | M6: =K6*L6 -> 1336461.8 | N6: 0.8 | O6: No major change
B7: Power Grid Corporation | C7: Power Transmission & Utilities | D7: ='Phase 1 (Jun 2025 - Apr 2028)'!D7 -> 0.028201635 | E7: =D7 -> 0.028201635 | F7: =$C$1*E7 -> 387279.16 | G7: 0.1197 | H7: ='Phase 1 (Jun 2025 - Apr 2028)'!J7 -> 406.45793 | I7: 1.2 | J7: =I7*G7 -> 0.14364 | K7: =H7*(1+J7)^2.67 -> 581.63179 | L7: =F7/H7 -> 952.81486 | M7: =K7*L7 -> 554187.41 | N7: 0.9 | O7: Large investment in transmission infrastructure and EV charging network expansion.
B8: Reliance Industries | C8: Energy, Oil & Gas | D8: ='Phase 1 (Jun 2025 - Apr 2028)'!D8 -> 0.053019074 | E8: =D8 -> 0.053019074 | F8: =$C$1*E8 -> 728084.82 | G8: 0.1985 | H8: ='Phase 1 (Jun 2025 - Apr 2028)'!J8 -> 2524.4479 | I8: 1.1 | J8: =I8*G8 -> 0.21835 | K8: =H8*(1+J8)^2.67 -> 4277.38 | L8: =F8/H8 -> 288.41348 | M8: =K8*L8 -> 1233654.1 | N8: 1 | O8: Strong participation in New Energy, battery ecosystem and green hydrogen.
B9: Persistent Systems | C9: Digital Engineering & IT Services | D9: ='Phase 1 (Jun 2025 - Apr 2028)'!D10 -> 0.10254545 | E9: =D9+1% -> 0.11254545 | F9: =$C$1*E9 -> 1545531.3 | G9: 0.3213 | H9: ='Phase 1 (Jun 2025 - Apr 2028)'!J10 -> 13047.54 | I9: 0.95 | J9: =I9*G9 -> 0.305235 | K9: =H9*(1+J9)^2.67 -> 26571.586 | L9: =F9/H9 -> 118.45385 | M9: =K9*L9 -> 3147506.7 | N9: 0.9 | O9: No major change
B10: Cummins India | C10: Capital Goods & Industrial Engineering | D10: ='Phase 1 (Jun 2025 - Apr 2028)'!D11 -> 0.094909091 | E10: =D10+1% -> 0.10490909 | F10: =$C$1*E10 -> 1440664.9 | G10: 0.1665 | H10: ='Phase 1 (Jun 2025 - Apr 2028)'!J11 -> 5399.3322 | I10: 1.2 | J10: =I10*G10 -> 0.1998 | K10: =H10*(1+J10)^2.67 -> 8781.3381 | L10: =F10/H10 -> 266.82279 | M10: =K10*L10 -> 2343061.1 | N10: 1.1 | O10: Higher industrial capex and infrastructure demand.
B11: Tata Elxsi | C11: Engineering R&D / Automotive Software | D11: ='Phase 1 (Jun 2025 - Apr 2028)'!D12 -> 0.078545455 | E11: =D11 -> 0.078545455 | F11: =$C$1*E11 -> 1078626 | G11: 0.2212 | H11: ='Phase 1 (Jun 2025 - Apr 2028)'!J12 -> 11349.617 | I11: 1.15 | J11: =I11*G11 -> 0.25438 | K11: =H11*(1+J11)^2.67 -> 20786.767 | L11: =F11/H11 -> 95.036339 | M11: =K11*L11 -> 1975498.3 | N11: 0.9 | O11: Direct exposure to EV software, automotive electronics and mobility solutions.
B12: Exide Industries | C12: Battery Manufacturing & Energy Storage | D12: 0 | E12: 0.05 | F12: =$C$1*E12 -> 686625.37 | G12: 0.0805 | H12: =388.45*(1+G12)^2.91 -> 486.61244 | I12: 2.3 | J12: =I12*G12 -> 0.18515 | K12: =H12*(1+J12)^2.67 -> 765.87515 | L12: =F12/H12 -> 1411.0313 | M12: =K12*L12 -> 1080673.8 | N12: 1.2 | O12: Lithium-ion cell manufacturing becomes a core growth driver. Historical CAGR understates future potential.
B13: Data Patterns | C13: Defence & Drone Technology | D13: 0.043125 | E13: =D13 -> 0.043125 | F13: =$C$1*E13 -> 592214.38 | G13: 0.1472 | H13: ='Phase 1 (Jun 2025 - Apr 2028)'!J13 -> 4616.5564 | I13: 1.2 | J13: =I13*G13 -> 0.17664 | K13: =H13*(1+J13)^2.67 -> 7127.4894 | L13: =F13/H13 -> 128.28055 | M13: =K13*L13 -> 914318.24 | N13: 1.1 | O13: No major change
B14: Neuland Laboratories | C14: Pharmaceuticals (APIs & Specialty Pharma) | D14: 0.048875 | E14: =D14 -> 0.048875 | F14: =$C$1*E14 -> 671176.3 | G14: 0.3224 | H14: ='Phase 1 (Jun 2025 - Apr 2028)'!J14 -> 25437.558 | I14: 0.8 | J14: =I14*G14 -> 0.25792 | K14: =H14*(1+J14)^2.67 -> 46940.638 | L14: =F14/H14 -> 26.385249 | M14: =K14*L14 -> 1238540.4 | N14: 0.8 | O14: No major change
B15: HBL Engineering | C15: Railway Electronics & Defence Systems | D15: 0.056925 | E15: =D15 -> 0.056925 | F15: =$C$1*E15 -> 781722.98 | G15: 0.3163 | H15: ='Phase 1 (Jun 2025 - Apr 2028)'!J15 -> 1305.9425 | I15: 1.1 | J15: =I15*G15 -> 0.34793 | K15: =H15*(1+J15)^2.67 -> 2898.25 | L15: =F15/H15 -> 598.58913 | M15: =K15*L15 -> 1734861 | N15: 1.4 | O15: No major change
B16: Amara Raja Energy & Mobility | C16: Battery Manufacturing & EV Energy Solutions | D16: 0 | E16: 0.0425 | F16: =$C$1*E16 -> 583631.56 | G16: 0.0153 | H16: =970*(1+G16)^2.91 -> 1013.8213 | I16: 11.5 | J16: =I16*G16 -> 0.17595 | K16: =H16*(1+J16)^2.67 -> 1562.7865 | L16: =F16/H16 -> 575.675 | M16: =K16*L16 -> 899657.11 | N16: 1.1 | O16: Historic stock CAGR reflects legacy business; future outlook changes significantly due to lithium-ion and energy storage investments.
B17: Nuvama Wealth Management | C17: Financial Services & Wealth Management | D17: 0.0506 | E17: =D17 -> 0.0506 | F17: =$C$1*E17 -> 694864.87 | G17: 0.5092 | H17: ='Phase 1 (Jun 2025 - Apr 2028)'!J17 -> 4970.0597 | I17: 0.9 | J17: =I17*G17 -> 0.45828 | K17: =H17*(1+J17)^2.67 -> 13608.707 | L17: =F17/H17 -> 139.81017 | M17: =K17*L17 -> 1902635.6 | N17: 1.4 | O17: No major change
B18: Nippon India ETF Gold BeES | C18: Commodity | D18: 0.05 | E18: 0.03 | F18: =$C$1*E18 -> 411975.22 | G18: 0.1387 | H18: ='Phase 1 (Jun 2025 - Apr 2028)'!J18 -> 116.12233 | I18: 1 | J18: =I18*G18 -> 0.1387 | K18: =H18*(1+J18)^2.67 -> 164.25879 | L18: =F18/H18 -> 3547.7692 | M18: =K18*L18 -> 582752.28 | N18: 0.1 | O18: No major change
B19: Bharat Bond ETF April 2030 | C19: Fixed Income (Debt Instruments) | D19: 0.03 | E19: =D19 -> 0.03 | F19: =$C$1*E19 -> 411975.22 | G19: 0.0756 | H19: ='Phase 1 (Jun 2025 - Apr 2028)'!J19 -> 1898.8691 | I19: 1 | J19: =I19*G19 -> 0.0756 | K19: =H19*(1+J19)^2.67 -> 2306.7612 | L19: =F19/H19 -> 216.9582 | M19: =K19*L19 -> 500470.77 | N19: 0.48 | O19: No major change
B20: Total | E20: =SUM(E3:E19) -> 0.9999814 | F20: =SUM(F3:F19) -> 13732252 | M20: =SUM(M3:M19) -> 23431711
B23: Risk Free Rate (Rf) | C23: 0.06
B24: Market Returns Rate (Rm) | C24: 0.107
B25: Projected Returns at the end of Apr 2028 | C25: =M20 -> 23431711 | M25: Large Cap
B26: Beta of the portfolio | C26: =SUMPRODUCT(E3:E19,N3:N19) -> 0.95453565 | M26: Medium Cap
B27: Portfolio Returns (Rp) | C27: =SUMPRODUCT(E3:E19,J3:J19) -> 0.21598516 | M27: Small Cap
B28: Sigma | C28: =_xlfn.STDEV.P((J3:J19)) -> 0.093141206
B29: Sharpe Ratio | C29: =(C27-C23)/C28 -> 1.674717
B30: Treynor Ratio | C30: =(C27-C23)/C26 -> 0.1634147
B31: Jensen Alpha | C31: =C27-(C23+(C24-C23)*C26) -> 0.11112199
B35: Notes:
B37: Tactical Rebalancing – Lithium Discovery Scenario (May 2028)
B39: Scenario Trigger
B41: In May 2028, significant lithium reserves were discovered in India, creating a major structural opportunity for the domestic EV ecosystem, battery manufacturing, renewable energy storage, and supporting infrastructure industries.
B43: The Investment Committee reviewed the existing portfolio to evaluate the impact of this development on future earnings growth, sector attractiveness, and company-level growth assumptions.
B45: Portfolio Rebalancing Strategy
B47: Instead of reconstructing the portfolio completely, the existing investment universe was retained as the companies had already passed fundamental screening criteria.
B49: The portfolio was tactically rebalanced by increasing exposure towards companies expected to benefit from the lithium value chain, while reducing allocation towards businesses with relatively lower incremental benefit from this macroeconomic development.
B51: Major portfolio actions:
B53: Increased exposure towards battery manufacturing and EV ecosystem companies.
B54: Added Exide Industries and Amara Raja Energy & Mobility to capture lithium-ion battery opportunities.
...

Sheet Phase 3 (Jan 31 - Jun 33)
B1: Investment amount | C1: ='Phase 2 (May 2028 - Dec 2030)'!M20 -> 23431711 | F1: Required CAGR | G1: 0.1835 | J1: Investemnt Horizon | K1: 8 | M1: Minimum Required Returns
B2: Investment amount after Downpayment | C2: =C1-5000000 -> 18431711 | N2: 30800000
B3: Stock | C3: Sector | D3: Previous Allocation (%) | E3: Updated Allocation(%) | F3: Investment Amount (₹) | G3: CAGR (Past 10Y) | H3: Current Price (Jan 2031) | I3: Adjustment Factor | J3: Expected CAGR | K3: Projected Value (Jun 2033) | L3: Shares Purchased | M3: Projected Returns (₹) | N3: Beta (3y)
B4: HDFC Bank | C4: Banking & Financial Services | D4: ='Phase 2 (May 2028 - Dec 2030)'!E3 -> 0.058659401 | E4: 0.105 | F4: =$C$2*E4 -> 1935329.6 | G4: 0.1266 | H4: ='Phase 2 (May 2028 - Dec 2030)'!K3 -> 2052.9317 | I4: 1.05 | J4: =I4*G4 -> 0.13293 | K4: =H4*(1+J4)^2.5 -> 2804.6727 | L4: =F4/H4 -> 942.71506 | M4: =L4*K4 -> 2644007.2 | N4: 1
B5: ICICI Bank | C5: Banking & Financial Services | D5: ='Phase 2 (May 2028 - Dec 2030)'!E4 -> 0.066555858 | E5: 0.095 | F5: =$C$2*E5 -> 1751012.5 | G5: 0.1965 | H5: ='Phase 2 (May 2028 - Dec 2030)'!K4 -> 3969.7453 | I5: 1 | J5: =I5*G5 -> 0.1965 | K5: =H5*(1+J5)^2.5 -> 6216.478 | L5: =F5/H5 -> 441.08938 | M5: =L5*K5 -> 2742022.4 | N5: 0.9
B6: Tata Consultancy Services (TCS) | C6: Information Technology Services | D6: ='Phase 2 (May 2028 - Dec 2030)'!E5 -> 0.074452316 | E6: 0.07 | F6: =$C$2*E6 -> 1290219.7 | G6: 0.1061 | H6: ='Phase 2 (May 2028 - Dec 2030)'!K5 -> 6042.0397 | I6: 1 | J6: =I6*G6 -> 0.1061 | K6: =H6*(1+J6)^2.5 -> 7774.4479 | L6: =F6/H6 -> 213.54043 | M6: =L6*K6 -> 1660158.9 | N6: 0.7
B7: Infosys | C7: Information Technology Services | D7: ='Phase 2 (May 2028 - Dec 2030)'!E6 -> 0.07106812 | E7: 0.065 | F7: =$C$2*E7 -> 1198061.2 | G7: 0.1157 | H7: ='Phase 2 (May 2028 - Dec 2030)'!K6 -> 3163.5896 | I7: 1 | J7: =I7*G7 -> 0.1157 | K7: =H7*(1+J7)^2.5 -> 4159.5727 | L7: =F7/H7 -> 378.7031 | M7: =L7*K7 -> 1575243.1 | N7: 0.8
B8: Power Grid Corporation | C8: Power Transmission & Utilities | D8: ='Phase 2 (May 2028 - Dec 2030)'!E7 -> 0.028201635 | E8: 0.055 | F8: =$C$2*E8 -> 1013744.1 | G8: 0.1197 | H8: ='Phase 2 (May 2028 - Dec 2030)'!K7 -> 581.63179 | I8: 1.15 | J8: =I8*G8 -> 0.137655 | K8: =H8*(1+J8)^2.5 -> 802.92427 | L8: =F8/H8 -> 1742.931 | M8: =L8*K8 -> 1399441.6 | N8: 0.9
B9: Reliance Industries | C9: Energy, Oil & Gas / New Energy & Digital Infrastructure | D9: ='Phase 2 (May 2028 - Dec 2030)'!E8 -> 0.053019074 | E9: 0.08 | F9: =$C$2*E9 -> 1474536.8 | G9: 0.1985 | H9: ='Phase 2 (May 2028 - Dec 2030)'!K8 -> 4277.38 | I9: 1.05 | J9: =I9*G9 -> 0.208425 | K9: =H9*(1+J9)^2.5 -> 6866.3683 | L9: =F9/H9 -> 344.72898 | M9: =L9*K9 -> 2367036.1 | N9: 1
B10: Larsen & Toubro (L&T) | C10: Infrastructure, Capital Goods & Engineering | D10: 0 | E10: 0.095 | F10: =$C$2*E10 -> 1751012.5 | G10: 0.1367 | H10: =3669*(1+G10)^5.58 -> 7499.8333 | I10: 1.15 | J10: =I10*G10 -> 0.157205 | K10: =H10*(1+J10)^2.5 -> 10803.821 | L10: =F10/H10 -> 233.47352 | M10: =L10*K10 -> 2522406.1 | N10: 1.3
B11: Hindustan Unilever (HUL) | C11: FMCG (Consumer Staples) | D11: 0 | E11: 0.05 | F11: =$C$2*E11 -> 921585.53 | G11: 0.0957 | H11: =2207*(1+G11)^5.58 -> 3675.207 | I11: 1 | J11: =I11*G11 -> 0.0957 | K11: =H11*(1+J11)^2.5 -> 4618.6065 | L11: =F11/H11 -> 250.75745 | M11: =L11*K11 -> 1158150 | N11: 0.4
B12: Sun Pharmaceutical Industries | C12: Pharmaceuticals & Healthcare | D12: 0 | E12: 0.06 | F12: =$C$2*E12 -> 1105902.6 | G12: 0.0736 | H12: =1687*(1+G12)^5.58 -> 2507.3574 | I12: 1.05 | J12: =I12*G12 -> 0.07728 | K12: =H12*(1+J12)^2.5 -> 3020.2142 | L12: =F12/H12 -> 441.06302 | M12: =L12*K12 -> 1332104.8 | N12: 0.5
B13: Persistent Systems | C13: Digital Engineering & IT Services | D13: ='Phase 2 (May 2028 - Dec 2030)'!E9 -> 0.11254545 | E13: 0.055 | F13: =$C$2*E13 -> 1013744.1 | G13: 0.3213 | H13: ='Phase 2 (May 2028 - Dec 2030)'!K9 -> 26571.586 | I13: 0.8 | J13: =I13*G13 -> 0.25704 | K13: =H13*(1+J13)^2.5 -> 47074.989 | L13: =F13/H13 -> 38.151433 | M13: =L13*K13 -> 1795978.3 | N13: 0.9
B14: Cummins India | C14: Capital Goods & Industrial Engineering | D14: ='Phase 2 (May 2028 - Dec 2030)'!E10 -> 0.10490909 | E14: 0.055 | F14: =$C$2*E14 -> 1013744.1 | G14: 0.1665 | H14: ='Phase 2 (May 2028 - Dec 2030)'!K10 -> 8781.3381 | I14: 1.1 | J14: =I14*G14 -> 0.18315 | K14: =H14*(1+J14)^2.5 -> 13370.887 | L14: =F14/H14 -> 115.44301 | M14: =L14*K14 -> 1543575.4 | N14: 1.1
B15: Tata Elxsi | C15: Engineering R&D / Automotive Software | D15: ='Phase 2 (May 2028 - Dec 2030)'!E11 -> 0.078545455 | E15: 0.04 | F15: =$C$2*E15 -> 737268.42 | G15: 0.2212 | H15: ='Phase 2 (May 2028 - Dec 2030)'!K11 -> 20786.767 | I15: 0.9 | J15: =I15*G15 -> 0.19908 | K15: =H15*(1+J15)^2.5 -> 32727.087 | L15: =F15/H15 -> 35.468162 | M15: =L15*K15 -> 1160769.6 | N15: 0.9
B16: Exide Industries | C16: Battery Manufacturing & Energy Storage | D16: ='Phase 2 (May 2028 - Dec 2030)'!E12 -> 0.05 | E16: 0.035 | F16: =$C$2*E16 -> 645109.87 | G16: 0.0805 | H16: ='Phase 2 (May 2028 - Dec 2030)'!K12 -> 765.87515 | I16: 2 | J16: =I16*G16 -> 0.161 | K16: =H16*(1+J16)^2.5 -> 1112.3425 | L16: =F16/H16 -> 842.31728 | M16: =L16*K16 -> 936945.3 | N16: 1.2
B17: Data Patterns | C17: Defence Electronics & Aerospace Technology | D17: ='Phase 2 (May 2028 - Dec 2030)'!E13 -> 0.043125 | E17: 0.025 | F17: =$C$2*E17 -> 460792.76 | G17: 0.1472 | H17: ='Phase 2 (May 2028 - Dec 2030)'!K13 -> 7127.4894 | I17: 1.15 | J17: =I17*G17 -> 0.16928 | K17: =H17*(1+J17)^2.5 -> 10537.386 | L17: =F17/H17 -> 64.65008 | M17: =L17*K17 -> 681242.84 | N17: 1.1
B18: Amara Raja Energy & Mobility | C18: Battery Manufacturing & EV Energy Solutions | D18: ='Phase 2 (May 2028 - Dec 2030)'!E16 -> 0.0425 | E18: 0.025 | F18: =$C$2*E18 -> 460792.76 | G18: 0.0153 | H18: ='Phase 2 (May 2028 - Dec 2030)'!K16 -> 1562.7865 | I18: 10 | J18: =I18*G18 -> 0.153 | K18: =H18*(1+J18)^2.5 -> 2230.8631 | L18: =F18/H18 -> 294.85331 | M18: =L18*K18 -> 657777.35 | N18: 1.1
B19: Nippon India ETF Gold BeES | C19: Commodity (Gold ETF) | D19: ='Phase 2 (May 2028 - Dec 2030)'!E18 -> 0.03 | E19: 0.06 | F19: =$C$2*E19 -> 1105902.6 | G19: 0.1387 | H19: ='Phase 2 (May 2028 - Dec 2030)'!K18 -> 164.25879 | I19: 1 | J19: =I19*G19 -> 0.1387 | K19: =H19*(1+J19)^2.5 -> 227.27513 | L19: =F19/H19 -> 6732.6846 | M19: =L19*K19 -> 1530171.8 | N19: 0.1
B20: Bharat Bond ETF April 2030 | C20: Fixed Income (Debt Instruments) | D20: ='Phase 2 (May 2028 - Dec 2030)'!E19 -> 0.03 | E20: 0.03 | F20: =$C$2*E20 -> 552951.32 | G20: 0.0756 | H20: ='Phase 2 (May 2028 - Dec 2030)'!K19 -> 2306.7612 | I20: 1 | J20: =I20*G20 -> 0.0756 | K20: =H20*(1+J20)^2.5 -> 2767.7676 | L20: =F20/H20 -> 239.70895 | M20: =L20*K20 -> 663458.68 | N20: 0.48
B21: Total | E21: =SUM(E4:E20) -> 1 | F21: =SUM(F4:F20) -> 18431711 | M21: =SUM(M4:M20) -> 26370489
L22: Downpayment | M22: 5000000
B23: Risk Free Rate (Rf) | C23: 0.06
B24: Market Returns Rate (Rm) | C24: 0.107 | L24: Total Returns | M24: =M21+M22 -> 31370489
B25: Projected Returns at the end of Apr 2028 | C25: =M21 -> 26370489
B26: Beta of the portfolio | C26: =SUMPRODUCT(E4:E20,N4:N20) -> 0.8579
B27: Portfolio Returns (Rp) | C27: =SUMPRODUCT(E4:E20,J4:J20) -> 0.1526296 | K27: Strategic Change :
B28: Sigma | C28: =_xlfn.STDEV.P((J4:J20)) -> 0.047607346 | K28: Reducing the risk through investing less in mid and small cap companies
B29: Sharpe Ratio | C29: =(C27-C23)/C28 -> 1.9456997 | K29: Category | L29: Phase 1 | M29: Phase 2 | N29: Phase 3
B30: Treynor Ratio | C30: =(C27-C23)/C26 -> 0.10797249 | K30: Large | L30: 0.414 | M30: 0.3519564 | N30: =SUM(E4:E12) -> 0.675
B31: Jensen Alpha | C31: =C27-(C23+(C24-C23)*C26) -> 0.0523083 | K31: Mid | L31: 0.276 | M31: 0.276 | N31: =SUM(E13:E15) -> 0.15
K32: Small | L32: 0.23 | M32: 0.292025 | N32: =SUM(E16:E18) -> 0.085
K33: Gold | L33: 0.05 | M33: 0.05 | N33: =E19 -> 0.06
K34: Bond | L34: 0.03 | M34: 0.03 | N34: =E20 -> 0.03
K35: Total | L35: =SUM(L30:L34) -> 1 | M35: =SUM(M30:M34) -> 0.9999814 | N35: =SUM(N30:N34) -> 1
B37: Notes:
L38: Large Cap
B39: Final Rebalancing – Tech Sovereignty & Wealth Preservation Phase (Jan 2031) | L39: Medium Cap
L40: Small Cap
B41: Scenario Trigger
...

Sheet Rationale Behind Adj. Factors
B1: Company | C1: Ideal Case (8Y) | D1: Phase 1 (2025-28) | E1: Phase 2 Lithium (2028-31) | F1: Phase 3 Tech Sovereignty (2031-33)
B2: HDFC Bank | C2: 1.05 – Long-term credit growth, stable earnings support historical CAGR continuation. | D2: 1.05 – Similar growth visibility maintained over shorter period. | E2: 1.10 – Manufacturing growth improves corporate lending opportunities. | F2: 1.05 – Mature banking franchise continues stable compounding.
B3: ICICI Bank | C3: 0.95 – Strong past performance but valuation rerating expected to normalize. | D3: 1.00 – Banking momentum expected to continue over 3Y. | E3: 1.05 – Higher capex cycle supports loan growth. | F3: 1.00 – Strong fundamentals support historical growth continuation.
B4: TCS | C4: 1.00 – Mature IT leader; historical growth considered sustainable. | D4: 1.00 – Cloud/AI demand maintains growth trajectory. | E4: 1.00 – No direct lithium impact. | F4: 1.00 – Low tariff exposure due to service-driven model.
B5: Infosys | C5: 1.08 – AI adoption and digital transformation provide upside. | D5: 1.08 – Enterprise digital spending supports near-term growth. | E5: 1.08 – Technology demand remains unchanged. | F5: 1.00 – Growth normalized as mature IT player.
B6: Power Grid | C6: 1.05 – Renewable transmission expansion supports growth. | D6: 1.10 – Infrastructure spending improves near-term visibility. | E6: 1.20 – EV ecosystem increases power transmission demand. | F6: 1.15 – Grid modernization benefits from domestic infrastructure focus.
B7: Reliance Industries | C7: 0.95 – Large size limits repeating historical high growth. | D7: 1.00 – Jio, retail and new energy support continuation. | E7: 1.10 – Lithium ecosystem and energy transition improve outlook. | F7: 1.05 – Domestic manufacturing initiatives support growth.
B8: ITC | C8: 1.15 – FMCG expansion and restructuring improve future prospects. | D8: 1.10 – Consumption growth continues but upside limited. | E8: NIL | F8: NIL
B9: Persistent Systems | C9: 0.84 – High growth company, but sustaining 30%+ CAGR for 8Y unlikely. | D9: 0.95 – AI/digital engineering momentum can sustain in shorter horizon. | E9: 0.95 – Limited lithium impact; IT growth continues. | F9: 0.85 – Strong company but growth normalizes with scale.
B10: Cummins India | C10: 1.08 – Manufacturing cycle and exports support growth. | D10: 1.15 – Strong industrial capex cycle. | E10: 1.20 – Domestic manufacturing acceleration increases demand. | F10: 1.10 – Tech Sovereignty supports industrial ecosystem.
B11: Tata Elxsi | C11: 0.90 – EV theme positive but premium valuation limits upside. | D11: 1.00 – EV software demand supports near-term growth. | E11: 1.15 – Lithium adoption accelerates automotive R&D demand. | F11: 0.95 – EV growth continues but component disruption creates pressure.
B12: Data Patterns | C12: 1.15 – Defence indigenization supports long-term growth. | D12: 1.25 – Defence spending and low base enable higher growth continuation. | E12: 1.20 – Domestic electronics demand remains supportive. | F12: 1.15 – Tech Sovereignty benefits defence electronics.
... B23: Bharat Bond ETF | C23: 1.00 – Yield-based predictable return. | D23: 1.00 – Fixed income return stability. | E23: 1.00 – Stable debt instrument. | F23: 1.00 – Capital preservation objective.
